Traceback (most recent call last):
  File "/usr/share/miniconda/lib/python3.9/site-packages/jupyter_cache/executors/utils.py", line 51, in single_nb_execution
    executenb(
  File "/usr/share/miniconda/lib/python3.9/site-packages/nbclient/client.py", line 1204, in execute
    return NotebookClient(nb=nb, resources=resources, km=km, **kwargs).execute()
  File "/usr/share/miniconda/lib/python3.9/site-packages/nbclient/util.py", line 84, in wrapped
    return just_run(coro(*args, **kwargs))
  File "/usr/share/miniconda/lib/python3.9/site-packages/nbclient/util.py", line 62, in just_run
    return loop.run_until_complete(coro)
  File "/usr/share/miniconda/lib/python3.9/asyncio/base_events.py", line 647, in run_until_complete
    return future.result()
  File "/usr/share/miniconda/lib/python3.9/site-packages/nbclient/client.py", line 663, in async_execute
    await self.async_execute_cell(
  File "/usr/share/miniconda/lib/python3.9/site-packages/nbclient/client.py", line 965, in async_execute_cell
    await self._check_raise_for_error(cell, cell_index, exec_reply)
  File "/usr/share/miniconda/lib/python3.9/site-packages/nbclient/client.py", line 862, in _check_raise_for_error
    raise CellExecutionError.from_cell_and_msg(cell, exec_reply_content)
nbclient.exceptions.CellExecutionError: An error occurred while executing the following cell:
------------------
mask_2sigma = make_source_mask(scene-bkg.background, nsigma=2, npixels=3,
                               dilate_size=5, filter_fwhm=3)
mask_3sigma = make_source_mask(scene-bkg.background, nsigma=3, npixels=3,
                               dilate_size=5, filter_fwhm=3)
plot_two(mask_2sigma, mask_3sigma, 0, 1)
------------------

[0;31m---------------------------------------------------------------------------[0m
[0;31mTypeError[0m                                 Traceback (most recent call last)
Cell [0;32mIn[25], line 1[0m
[0;32m----> 1[0m mask_2sigma [38;5;241m=[39m [43mmake_source_mask[49m[43m([49m[43mscene[49m[38;5;241;43m-[39;49m[43mbkg[49m[38;5;241;43m.[39;49m[43mbackground[49m[43m,[49m[43m [49m[43mnsigma[49m[38;5;241;43m=[39;49m[38;5;241;43m2[39;49m[43m,[49m[43m [49m[43mnpixels[49m[38;5;241;43m=[39;49m[38;5;241;43m3[39;49m[43m,[49m
[1;32m      2[0m [43m                               [49m[43mdilate_size[49m[38;5;241;43m=[39;49m[38;5;241;43m5[39;49m[43m,[49m[43m [49m[43mfilter_fwhm[49m[38;5;241;43m=[39;49m[38;5;241;43m3[39;49m[43m)[49m
[1;32m      3[0m mask_3sigma [38;5;241m=[39m make_source_mask(scene[38;5;241m-[39mbkg[38;5;241m.[39mbackground, nsigma[38;5;241m=[39m[38;5;241m3[39m, npixels[38;5;241m=[39m[38;5;241m3[39m,
[1;32m      4[0m                                dilate_size[38;5;241m=[39m[38;5;241m5[39m, filter_fwhm[38;5;241m=[39m[38;5;241m3[39m)
[1;32m      5[0m plot_two(mask_2sigma, mask_3sigma, [38;5;241m0[39m, [38;5;241m1[39m)

File [0;32m/usr/share/miniconda/lib/python3.9/site-packages/astropy/utils/decorators.py:136[0m, in [0;36mdeprecated.<locals>.deprecate_function.<locals>.deprecated_func[0;34m(*args, **kwargs)[0m
[1;32m    132[0m     category [38;5;241m=[39m warning_type
[1;32m    134[0m warnings[38;5;241m.[39mwarn(message, category, stacklevel[38;5;241m=[39m[38;5;241m2[39m)
[0;32m--> 136[0m [38;5;28;01mreturn[39;00m [43mfunc[49m[43m([49m[38;5;241;43m*[39;49m[43margs[49m[43m,[49m[43m [49m[38;5;241;43m*[39;49m[38;5;241;43m*[39;49m[43mkwargs[49m[43m)[49m

[0;31mTypeError[0m: make_source_mask() got an unexpected keyword argument 'filter_fwhm'
TypeError: make_source_mask() got an unexpected keyword argument 'filter_fwhm'

